{"trial_id": "01", "hyperparameters": {"space": [{"class_name": "Int", "config": {"name": "filters", "default": null, "conditions": [], "min_value": 32, "max_value": 128, "step": 32, "sampling": "linear"}}, {"class_name": "Int", "config": {"name": "lstm_units", "default": null, "conditions": [], "min_value": 32, "max_value": 128, "step": 32, "sampling": "linear"}}, {"class_name": "Int", "config": {"name": "lstm_units_2", "default": null, "conditions": [], "min_value": 32, "max_value": 128, "step": 32, "sampling": "linear"}}, {"class_name": "Choice", "config": {"name": "learning_rate", "default": 0.01, "conditions": [], "values": [0.01, 0.001, 0.0001], "ordered": true}}], "values": {"filters": 128, "lstm_units": 128, "lstm_units_2": 32, "learning_rate": 0.0001}}, "metrics": {"metrics": {}}, "score": null, "best_step": 0, "status": "FAILED", "message": "Traceback (most recent call last):\n  File \"C:\\Users\\chris\\anaconda3\\lib\\site-packages\\keras_tuner\\src\\engine\\base_tuner.py\", line 274, in _try_run_and_update_trial\n    self._run_and_update_trial(trial, *fit_args, **fit_kwargs)\n  File \"C:\\Users\\chris\\anaconda3\\lib\\site-packages\\keras_tuner\\src\\engine\\base_tuner.py\", line 239, in _run_and_update_trial\n    results = self.run_trial(trial, *fit_args, **fit_kwargs)\n  File \"C:\\Users\\chris\\anaconda3\\lib\\site-packages\\keras_tuner\\src\\engine\\tuner.py\", line 314, in run_trial\n    obj_value = self._build_and_fit_model(trial, *args, **copied_kwargs)\n  File \"C:\\Users\\chris\\anaconda3\\lib\\site-packages\\keras_tuner\\src\\engine\\tuner.py\", line 233, in _build_and_fit_model\n    results = self.hypermodel.fit(hp, model, *args, **kwargs)\n  File \"C:\\Users\\chris\\anaconda3\\lib\\site-packages\\keras_tuner\\src\\engine\\hypermodel.py\", line 149, in fit\n    return model.fit(*args, **kwargs)\n  File \"C:\\Users\\chris\\anaconda3\\lib\\site-packages\\keras\\utils\\traceback_utils.py\", line 70, in error_handler\n    raise e.with_traceback(filtered_tb) from None\n  File \"C:\\Users\\chris\\AppData\\Local\\Temp\\__autograph_generated_file3bfeexu2.py\", line 15, in tf__train_function\n    retval_ = ag__.converted_call(ag__.ld(step_function), (ag__.ld(self), ag__.ld(iterator)), None, fscope)\nValueError: in user code:\n\n    File \"C:\\Users\\chris\\anaconda3\\lib\\site-packages\\keras\\engine\\training.py\", line 1249, in train_function  *\n        return step_function(self, iterator)\n    File \"C:\\Users\\chris\\anaconda3\\lib\\site-packages\\keras\\engine\\training.py\", line 1233, in step_function  **\n        outputs = model.distribute_strategy.run(run_step, args=(data,))\n    File \"C:\\Users\\chris\\anaconda3\\lib\\site-packages\\keras\\engine\\training.py\", line 1222, in run_step  **\n        outputs = model.train_step(data)\n    File \"C:\\Users\\chris\\anaconda3\\lib\\site-packages\\keras\\engine\\training.py\", line 1024, in train_step\n        loss = self.compute_loss(x, y, y_pred, sample_weight)\n    File \"C:\\Users\\chris\\anaconda3\\lib\\site-packages\\keras\\engine\\training.py\", line 1082, in compute_loss\n        return self.compiled_loss(\n    File \"C:\\Users\\chris\\anaconda3\\lib\\site-packages\\keras\\engine\\compile_utils.py\", line 265, in __call__\n        loss_value = loss_obj(y_t, y_p, sample_weight=sw)\n    File \"C:\\Users\\chris\\anaconda3\\lib\\site-packages\\keras\\losses.py\", line 152, in __call__\n        losses = call_fn(y_true, y_pred)\n    File \"C:\\Users\\chris\\anaconda3\\lib\\site-packages\\keras\\losses.py\", line 284, in call  **\n        return ag_fn(y_true, y_pred, **self._fn_kwargs)\n    File \"C:\\Users\\chris\\anaconda3\\lib\\site-packages\\keras\\losses.py\", line 1500, in mean_squared_error\n        return backend.mean(tf.math.squared_difference(y_pred, y_true), axis=-1)\n\n    ValueError: Dimensions must be equal, but are 10 and 3 for '{{node mean_squared_error/SquaredDifference}} = SquaredDifference[T=DT_FLOAT](sequential/reshape_1/Reshape, IteratorGetNext:1)' with input shapes: [32,10,50,3], [32,3,10,50].\n\n"}